Downloading shards:   0%|          | 0/8 [00:00<?, ?it/s]Downloading shards:  12%|█▎        | 1/8 [00:01<00:07,  1.09s/it]
Traceback (most recent call last):
  File "/home/ubuntu/yzq/gs-python/venv3.10/lib/python3.8/site-packages/transformers/utils/hub.py", line 417, in cached_file
    resolved_file = hf_hub_download(
  File "/home/ubuntu/yzq/gs-python/venv3.10/lib/python3.8/site-packages/huggingface_hub/utils/_validators.py", line 118, in _inner_fn
    return fn(*args, **kwargs)
  File "/home/ubuntu/yzq/gs-python/venv3.10/lib/python3.8/site-packages/huggingface_hub/file_download.py", line 1291, in hf_hub_download
    raise LocalEntryNotFoundError(
huggingface_hub.utils._errors.LocalEntryNotFoundError: Connection error, and we cannot find the requested files in the disk cache. Please try again or make sure your Internet connection is on.

During handling of the above exception, another exception occurred:

Traceback (most recent call last):
  File "chatglm.py", line 13, in <module>
    model = AutoModel.from_pretrained("THUDM/chatglm-6b", trust_remote_code=True).half().cuda()
  File "/home/ubuntu/yzq/gs-python/venv3.10/lib/python3.8/site-packages/transformers/models/auto/auto_factory.py", line 479, in from_pretrained
    return model_class.from_pretrained(
  File "/home/ubuntu/yzq/gs-python/venv3.10/lib/python3.8/site-packages/transformers/modeling_utils.py", line 2585, in from_pretrained
    resolved_archive_file, sharded_metadata = get_checkpoint_shard_files(
  File "/home/ubuntu/yzq/gs-python/venv3.10/lib/python3.8/site-packages/transformers/utils/hub.py", line 959, in get_checkpoint_shard_files
    cached_filename = cached_file(
  File "/home/ubuntu/yzq/gs-python/venv3.10/lib/python3.8/site-packages/transformers/utils/hub.py", line 452, in cached_file
    raise EnvironmentError(
OSError: We couldn't connect to 'https://huggingface.co' to load this file, couldn't find it in the cached files and it looks like THUDM/chatglm-6b is not the path to a directory containing a file named pytorch_model-00002-of-00008.bin.
Checkout your internet connection or see how to run the library in offline mode at 'https://huggingface.co/docs/transformers/installation#offline-mode'.
Downloading shards:   0%|          | 0/8 [00:00<?, ?it/s]Downloading shards:  12%|█▎        | 1/8 [00:01<00:09,  1.31s/it]
Traceback (most recent call last):
  File "/home/ubuntu/yzq/gs-python/venv3.10/lib/python3.8/site-packages/urllib3/connectionpool.py", line 790, in urlopen
    response = self._make_request(
  File "/home/ubuntu/yzq/gs-python/venv3.10/lib/python3.8/site-packages/urllib3/connectionpool.py", line 491, in _make_request
    raise new_e
  File "/home/ubuntu/yzq/gs-python/venv3.10/lib/python3.8/site-packages/urllib3/connectionpool.py", line 467, in _make_request
    self._validate_conn(conn)
  File "/home/ubuntu/yzq/gs-python/venv3.10/lib/python3.8/site-packages/urllib3/connectionpool.py", line 1092, in _validate_conn
    conn.connect()
  File "/home/ubuntu/yzq/gs-python/venv3.10/lib/python3.8/site-packages/urllib3/connection.py", line 635, in connect
    sock_and_verified = _ssl_wrap_socket_and_match_hostname(
  File "/home/ubuntu/yzq/gs-python/venv3.10/lib/python3.8/site-packages/urllib3/connection.py", line 774, in _ssl_wrap_socket_and_match_hostname
    ssl_sock = ssl_wrap_socket(
  File "/home/ubuntu/yzq/gs-python/venv3.10/lib/python3.8/site-packages/urllib3/util/ssl_.py", line 459, in ssl_wrap_socket
    ssl_sock = _ssl_wrap_socket_impl(sock, context, tls_in_tls, server_hostname)
  File "/home/ubuntu/yzq/gs-python/venv3.10/lib/python3.8/site-packages/urllib3/util/ssl_.py", line 503, in _ssl_wrap_socket_impl
    return ssl_context.wrap_socket(sock, server_hostname=server_hostname)
  File "/usr/lib/python3.8/ssl.py", line 500, in wrap_socket
    return self.sslsocket_class._create(
  File "/usr/lib/python3.8/ssl.py", line 1040, in _create
    self.do_handshake()
  File "/usr/lib/python3.8/ssl.py", line 1309, in do_handshake
    self._sslobj.do_handshake()
ConnectionResetError: [Errno 104] Connection reset by peer

During handling of the above exception, another exception occurred:

Traceback (most recent call last):
  File "/home/ubuntu/yzq/gs-python/venv3.10/lib/python3.8/site-packages/requests/adapters.py", line 486, in send
    resp = conn.urlopen(
  File "/home/ubuntu/yzq/gs-python/venv3.10/lib/python3.8/site-packages/urllib3/connectionpool.py", line 844, in urlopen
    retries = retries.increment(
  File "/home/ubuntu/yzq/gs-python/venv3.10/lib/python3.8/site-packages/urllib3/util/retry.py", line 470, in increment
    raise reraise(type(error), error, _stacktrace)
  File "/home/ubuntu/yzq/gs-python/venv3.10/lib/python3.8/site-packages/urllib3/util/util.py", line 38, in reraise
    raise value.with_traceback(tb)
  File "/home/ubuntu/yzq/gs-python/venv3.10/lib/python3.8/site-packages/urllib3/connectionpool.py", line 790, in urlopen
    response = self._make_request(
  File "/home/ubuntu/yzq/gs-python/venv3.10/lib/python3.8/site-packages/urllib3/connectionpool.py", line 491, in _make_request
    raise new_e
  File "/home/ubuntu/yzq/gs-python/venv3.10/lib/python3.8/site-packages/urllib3/connectionpool.py", line 467, in _make_request
    self._validate_conn(conn)
  File "/home/ubuntu/yzq/gs-python/venv3.10/lib/python3.8/site-packages/urllib3/connectionpool.py", line 1092, in _validate_conn
    conn.connect()
  File "/home/ubuntu/yzq/gs-python/venv3.10/lib/python3.8/site-packages/urllib3/connection.py", line 635, in connect
    sock_and_verified = _ssl_wrap_socket_and_match_hostname(
  File "/home/ubuntu/yzq/gs-python/venv3.10/lib/python3.8/site-packages/urllib3/connection.py", line 774, in _ssl_wrap_socket_and_match_hostname
    ssl_sock = ssl_wrap_socket(
  File "/home/ubuntu/yzq/gs-python/venv3.10/lib/python3.8/site-packages/urllib3/util/ssl_.py", line 459, in ssl_wrap_socket
    ssl_sock = _ssl_wrap_socket_impl(sock, context, tls_in_tls, server_hostname)
  File "/home/ubuntu/yzq/gs-python/venv3.10/lib/python3.8/site-packages/urllib3/util/ssl_.py", line 503, in _ssl_wrap_socket_impl
    return ssl_context.wrap_socket(sock, server_hostname=server_hostname)
  File "/usr/lib/python3.8/ssl.py", line 500, in wrap_socket
    return self.sslsocket_class._create(
  File "/usr/lib/python3.8/ssl.py", line 1040, in _create
    self.do_handshake()
  File "/usr/lib/python3.8/ssl.py", line 1309, in do_handshake
    self._sslobj.do_handshake()
urllib3.exceptions.ProtocolError: ('Connection aborted.', ConnectionResetError(104, 'Connection reset by peer'))

During handling of the above exception, another exception occurred:

Traceback (most recent call last):
  File "chatglm.py", line 13, in <module>
    model = AutoModel.from_pretrained("THUDM/chatglm-6b", trust_remote_code=True).half().cuda()
  File "/home/ubuntu/yzq/gs-python/venv3.10/lib/python3.8/site-packages/transformers/models/auto/auto_factory.py", line 479, in from_pretrained
    return model_class.from_pretrained(
  File "/home/ubuntu/yzq/gs-python/venv3.10/lib/python3.8/site-packages/transformers/modeling_utils.py", line 2585, in from_pretrained
    resolved_archive_file, sharded_metadata = get_checkpoint_shard_files(
  File "/home/ubuntu/yzq/gs-python/venv3.10/lib/python3.8/site-packages/transformers/utils/hub.py", line 959, in get_checkpoint_shard_files
    cached_filename = cached_file(
  File "/home/ubuntu/yzq/gs-python/venv3.10/lib/python3.8/site-packages/transformers/utils/hub.py", line 417, in cached_file
    resolved_file = hf_hub_download(
  File "/home/ubuntu/yzq/gs-python/venv3.10/lib/python3.8/site-packages/huggingface_hub/utils/_validators.py", line 118, in _inner_fn
    return fn(*args, **kwargs)
  File "/home/ubuntu/yzq/gs-python/venv3.10/lib/python3.8/site-packages/huggingface_hub/file_download.py", line 1364, in hf_hub_download
    http_get(
  File "/home/ubuntu/yzq/gs-python/venv3.10/lib/python3.8/site-packages/huggingface_hub/file_download.py", line 505, in http_get
    r = _request_wrapper(
  File "/home/ubuntu/yzq/gs-python/venv3.10/lib/python3.8/site-packages/huggingface_hub/file_download.py", line 442, in _request_wrapper
    return http_backoff(
  File "/home/ubuntu/yzq/gs-python/venv3.10/lib/python3.8/site-packages/huggingface_hub/utils/_http.py", line 212, in http_backoff
    response = session.request(method=method, url=url, **kwargs)
  File "/home/ubuntu/yzq/gs-python/venv3.10/lib/python3.8/site-packages/requests/sessions.py", line 589, in request
    resp = self.send(prep, **send_kwargs)
  File "/home/ubuntu/yzq/gs-python/venv3.10/lib/python3.8/site-packages/requests/sessions.py", line 703, in send
    r = adapter.send(request, **kwargs)
  File "/home/ubuntu/yzq/gs-python/venv3.10/lib/python3.8/site-packages/requests/adapters.py", line 501, in send
    raise ConnectionError(err, request=request)
requests.exceptions.ConnectionError: ('Connection aborted.', ConnectionResetError(104, 'Connection reset by peer'))
Downloading shards:   0%|          | 0/8 [00:00<?, ?it/s]Downloading shards:  12%|█▎        | 1/8 [00:00<00:02,  2.47it/s]
Traceback (most recent call last):
  File "/home/ubuntu/yzq/gs-python/venv3.10/lib/python3.8/site-packages/urllib3/connectionpool.py", line 790, in urlopen
    response = self._make_request(
  File "/home/ubuntu/yzq/gs-python/venv3.10/lib/python3.8/site-packages/urllib3/connectionpool.py", line 491, in _make_request
    raise new_e
  File "/home/ubuntu/yzq/gs-python/venv3.10/lib/python3.8/site-packages/urllib3/connectionpool.py", line 467, in _make_request
    self._validate_conn(conn)
  File "/home/ubuntu/yzq/gs-python/venv3.10/lib/python3.8/site-packages/urllib3/connectionpool.py", line 1092, in _validate_conn
    conn.connect()
  File "/home/ubuntu/yzq/gs-python/venv3.10/lib/python3.8/site-packages/urllib3/connection.py", line 635, in connect
    sock_and_verified = _ssl_wrap_socket_and_match_hostname(
  File "/home/ubuntu/yzq/gs-python/venv3.10/lib/python3.8/site-packages/urllib3/connection.py", line 774, in _ssl_wrap_socket_and_match_hostname
    ssl_sock = ssl_wrap_socket(
  File "/home/ubuntu/yzq/gs-python/venv3.10/lib/python3.8/site-packages/urllib3/util/ssl_.py", line 459, in ssl_wrap_socket
    ssl_sock = _ssl_wrap_socket_impl(sock, context, tls_in_tls, server_hostname)
  File "/home/ubuntu/yzq/gs-python/venv3.10/lib/python3.8/site-packages/urllib3/util/ssl_.py", line 503, in _ssl_wrap_socket_impl
    return ssl_context.wrap_socket(sock, server_hostname=server_hostname)
  File "/usr/lib/python3.8/ssl.py", line 500, in wrap_socket
    return self.sslsocket_class._create(
  File "/usr/lib/python3.8/ssl.py", line 1040, in _create
    self.do_handshake()
  File "/usr/lib/python3.8/ssl.py", line 1309, in do_handshake
    self._sslobj.do_handshake()
ConnectionResetError: [Errno 104] Connection reset by peer

During handling of the above exception, another exception occurred:

Traceback (most recent call last):
  File "/home/ubuntu/yzq/gs-python/venv3.10/lib/python3.8/site-packages/requests/adapters.py", line 486, in send
    resp = conn.urlopen(
  File "/home/ubuntu/yzq/gs-python/venv3.10/lib/python3.8/site-packages/urllib3/connectionpool.py", line 844, in urlopen
    retries = retries.increment(
  File "/home/ubuntu/yzq/gs-python/venv3.10/lib/python3.8/site-packages/urllib3/util/retry.py", line 470, in increment
    raise reraise(type(error), error, _stacktrace)
  File "/home/ubuntu/yzq/gs-python/venv3.10/lib/python3.8/site-packages/urllib3/util/util.py", line 38, in reraise
    raise value.with_traceback(tb)
  File "/home/ubuntu/yzq/gs-python/venv3.10/lib/python3.8/site-packages/urllib3/connectionpool.py", line 790, in urlopen
    response = self._make_request(
  File "/home/ubuntu/yzq/gs-python/venv3.10/lib/python3.8/site-packages/urllib3/connectionpool.py", line 491, in _make_request
    raise new_e
  File "/home/ubuntu/yzq/gs-python/venv3.10/lib/python3.8/site-packages/urllib3/connectionpool.py", line 467, in _make_request
    self._validate_conn(conn)
  File "/home/ubuntu/yzq/gs-python/venv3.10/lib/python3.8/site-packages/urllib3/connectionpool.py", line 1092, in _validate_conn
    conn.connect()
  File "/home/ubuntu/yzq/gs-python/venv3.10/lib/python3.8/site-packages/urllib3/connection.py", line 635, in connect
    sock_and_verified = _ssl_wrap_socket_and_match_hostname(
  File "/home/ubuntu/yzq/gs-python/venv3.10/lib/python3.8/site-packages/urllib3/connection.py", line 774, in _ssl_wrap_socket_and_match_hostname
    ssl_sock = ssl_wrap_socket(
  File "/home/ubuntu/yzq/gs-python/venv3.10/lib/python3.8/site-packages/urllib3/util/ssl_.py", line 459, in ssl_wrap_socket
    ssl_sock = _ssl_wrap_socket_impl(sock, context, tls_in_tls, server_hostname)
  File "/home/ubuntu/yzq/gs-python/venv3.10/lib/python3.8/site-packages/urllib3/util/ssl_.py", line 503, in _ssl_wrap_socket_impl
    return ssl_context.wrap_socket(sock, server_hostname=server_hostname)
  File "/usr/lib/python3.8/ssl.py", line 500, in wrap_socket
    return self.sslsocket_class._create(
  File "/usr/lib/python3.8/ssl.py", line 1040, in _create
    self.do_handshake()
  File "/usr/lib/python3.8/ssl.py", line 1309, in do_handshake
    self._sslobj.do_handshake()
urllib3.exceptions.ProtocolError: ('Connection aborted.', ConnectionResetError(104, 'Connection reset by peer'))

During handling of the above exception, another exception occurred:

Traceback (most recent call last):
  File "chatglm.py", line 13, in <module>
    model = AutoModel.from_pretrained("THUDM/chatglm-6b", trust_remote_code=True).half().cuda()
  File "/home/ubuntu/yzq/gs-python/venv3.10/lib/python3.8/site-packages/transformers/models/auto/auto_factory.py", line 479, in from_pretrained
    return model_class.from_pretrained(
  File "/home/ubuntu/yzq/gs-python/venv3.10/lib/python3.8/site-packages/transformers/modeling_utils.py", line 2585, in from_pretrained
    resolved_archive_file, sharded_metadata = get_checkpoint_shard_files(
  File "/home/ubuntu/yzq/gs-python/venv3.10/lib/python3.8/site-packages/transformers/utils/hub.py", line 959, in get_checkpoint_shard_files
    cached_filename = cached_file(
  File "/home/ubuntu/yzq/gs-python/venv3.10/lib/python3.8/site-packages/transformers/utils/hub.py", line 417, in cached_file
    resolved_file = hf_hub_download(
  File "/home/ubuntu/yzq/gs-python/venv3.10/lib/python3.8/site-packages/huggingface_hub/utils/_validators.py", line 118, in _inner_fn
    return fn(*args, **kwargs)
  File "/home/ubuntu/yzq/gs-python/venv3.10/lib/python3.8/site-packages/huggingface_hub/file_download.py", line 1364, in hf_hub_download
    http_get(
  File "/home/ubuntu/yzq/gs-python/venv3.10/lib/python3.8/site-packages/huggingface_hub/file_download.py", line 505, in http_get
    r = _request_wrapper(
  File "/home/ubuntu/yzq/gs-python/venv3.10/lib/python3.8/site-packages/huggingface_hub/file_download.py", line 442, in _request_wrapper
    return http_backoff(
  File "/home/ubuntu/yzq/gs-python/venv3.10/lib/python3.8/site-packages/huggingface_hub/utils/_http.py", line 212, in http_backoff
    response = session.request(method=method, url=url, **kwargs)
  File "/home/ubuntu/yzq/gs-python/venv3.10/lib/python3.8/site-packages/requests/sessions.py", line 589, in request
    resp = self.send(prep, **send_kwargs)
  File "/home/ubuntu/yzq/gs-python/venv3.10/lib/python3.8/site-packages/requests/sessions.py", line 703, in send
    r = adapter.send(request, **kwargs)
  File "/home/ubuntu/yzq/gs-python/venv3.10/lib/python3.8/site-packages/requests/adapters.py", line 501, in send
    raise ConnectionError(err, request=request)
requests.exceptions.ConnectionError: ('Connection aborted.', ConnectionResetError(104, 'Connection reset by peer'))
Downloading shards:   0%|          | 0/8 [00:00<?, ?it/s]Downloading shards:  12%|█▎        | 1/8 [00:00<00:02,  3.48it/s]
Traceback (most recent call last):
  File "/home/ubuntu/yzq/gs-python/venv3.10/lib/python3.8/site-packages/urllib3/connectionpool.py", line 790, in urlopen
    response = self._make_request(
  File "/home/ubuntu/yzq/gs-python/venv3.10/lib/python3.8/site-packages/urllib3/connectionpool.py", line 491, in _make_request
    raise new_e
  File "/home/ubuntu/yzq/gs-python/venv3.10/lib/python3.8/site-packages/urllib3/connectionpool.py", line 467, in _make_request
    self._validate_conn(conn)
  File "/home/ubuntu/yzq/gs-python/venv3.10/lib/python3.8/site-packages/urllib3/connectionpool.py", line 1092, in _validate_conn
    conn.connect()
  File "/home/ubuntu/yzq/gs-python/venv3.10/lib/python3.8/site-packages/urllib3/connection.py", line 635, in connect
    sock_and_verified = _ssl_wrap_socket_and_match_hostname(
  File "/home/ubuntu/yzq/gs-python/venv3.10/lib/python3.8/site-packages/urllib3/connection.py", line 774, in _ssl_wrap_socket_and_match_hostname
    ssl_sock = ssl_wrap_socket(
  File "/home/ubuntu/yzq/gs-python/venv3.10/lib/python3.8/site-packages/urllib3/util/ssl_.py", line 459, in ssl_wrap_socket
    ssl_sock = _ssl_wrap_socket_impl(sock, context, tls_in_tls, server_hostname)
  File "/home/ubuntu/yzq/gs-python/venv3.10/lib/python3.8/site-packages/urllib3/util/ssl_.py", line 503, in _ssl_wrap_socket_impl
    return ssl_context.wrap_socket(sock, server_hostname=server_hostname)
  File "/usr/lib/python3.8/ssl.py", line 500, in wrap_socket
    return self.sslsocket_class._create(
  File "/usr/lib/python3.8/ssl.py", line 1040, in _create
    self.do_handshake()
  File "/usr/lib/python3.8/ssl.py", line 1309, in do_handshake
    self._sslobj.do_handshake()
ConnectionResetError: [Errno 104] Connection reset by peer

During handling of the above exception, another exception occurred:

Traceback (most recent call last):
  File "/home/ubuntu/yzq/gs-python/venv3.10/lib/python3.8/site-packages/requests/adapters.py", line 486, in send
    resp = conn.urlopen(
  File "/home/ubuntu/yzq/gs-python/venv3.10/lib/python3.8/site-packages/urllib3/connectionpool.py", line 844, in urlopen
    retries = retries.increment(
  File "/home/ubuntu/yzq/gs-python/venv3.10/lib/python3.8/site-packages/urllib3/util/retry.py", line 470, in increment
    raise reraise(type(error), error, _stacktrace)
  File "/home/ubuntu/yzq/gs-python/venv3.10/lib/python3.8/site-packages/urllib3/util/util.py", line 38, in reraise
    raise value.with_traceback(tb)
  File "/home/ubuntu/yzq/gs-python/venv3.10/lib/python3.8/site-packages/urllib3/connectionpool.py", line 790, in urlopen
    response = self._make_request(
  File "/home/ubuntu/yzq/gs-python/venv3.10/lib/python3.8/site-packages/urllib3/connectionpool.py", line 491, in _make_request
    raise new_e
  File "/home/ubuntu/yzq/gs-python/venv3.10/lib/python3.8/site-packages/urllib3/connectionpool.py", line 467, in _make_request
    self._validate_conn(conn)
  File "/home/ubuntu/yzq/gs-python/venv3.10/lib/python3.8/site-packages/urllib3/connectionpool.py", line 1092, in _validate_conn
    conn.connect()
  File "/home/ubuntu/yzq/gs-python/venv3.10/lib/python3.8/site-packages/urllib3/connection.py", line 635, in connect
    sock_and_verified = _ssl_wrap_socket_and_match_hostname(
  File "/home/ubuntu/yzq/gs-python/venv3.10/lib/python3.8/site-packages/urllib3/connection.py", line 774, in _ssl_wrap_socket_and_match_hostname
    ssl_sock = ssl_wrap_socket(
  File "/home/ubuntu/yzq/gs-python/venv3.10/lib/python3.8/site-packages/urllib3/util/ssl_.py", line 459, in ssl_wrap_socket
    ssl_sock = _ssl_wrap_socket_impl(sock, context, tls_in_tls, server_hostname)
  File "/home/ubuntu/yzq/gs-python/venv3.10/lib/python3.8/site-packages/urllib3/util/ssl_.py", line 503, in _ssl_wrap_socket_impl
    return ssl_context.wrap_socket(sock, server_hostname=server_hostname)
  File "/usr/lib/python3.8/ssl.py", line 500, in wrap_socket
    return self.sslsocket_class._create(
  File "/usr/lib/python3.8/ssl.py", line 1040, in _create
    self.do_handshake()
  File "/usr/lib/python3.8/ssl.py", line 1309, in do_handshake
    self._sslobj.do_handshake()
urllib3.exceptions.ProtocolError: ('Connection aborted.', ConnectionResetError(104, 'Connection reset by peer'))

During handling of the above exception, another exception occurred:

Traceback (most recent call last):
  File "chatglm.py", line 13, in <module>
    model = AutoModel.from_pretrained("THUDM/chatglm-6b", trust_remote_code=True).half().cuda()
  File "/home/ubuntu/yzq/gs-python/venv3.10/lib/python3.8/site-packages/transformers/models/auto/auto_factory.py", line 479, in from_pretrained
    return model_class.from_pretrained(
  File "/home/ubuntu/yzq/gs-python/venv3.10/lib/python3.8/site-packages/transformers/modeling_utils.py", line 2585, in from_pretrained
    resolved_archive_file, sharded_metadata = get_checkpoint_shard_files(
  File "/home/ubuntu/yzq/gs-python/venv3.10/lib/python3.8/site-packages/transformers/utils/hub.py", line 959, in get_checkpoint_shard_files
    cached_filename = cached_file(
  File "/home/ubuntu/yzq/gs-python/venv3.10/lib/python3.8/site-packages/transformers/utils/hub.py", line 417, in cached_file
    resolved_file = hf_hub_download(
  File "/home/ubuntu/yzq/gs-python/venv3.10/lib/python3.8/site-packages/huggingface_hub/utils/_validators.py", line 118, in _inner_fn
    return fn(*args, **kwargs)
  File "/home/ubuntu/yzq/gs-python/venv3.10/lib/python3.8/site-packages/huggingface_hub/file_download.py", line 1364, in hf_hub_download
    http_get(
  File "/home/ubuntu/yzq/gs-python/venv3.10/lib/python3.8/site-packages/huggingface_hub/file_download.py", line 505, in http_get
    r = _request_wrapper(
  File "/home/ubuntu/yzq/gs-python/venv3.10/lib/python3.8/site-packages/huggingface_hub/file_download.py", line 442, in _request_wrapper
    return http_backoff(
  File "/home/ubuntu/yzq/gs-python/venv3.10/lib/python3.8/site-packages/huggingface_hub/utils/_http.py", line 212, in http_backoff
    response = session.request(method=method, url=url, **kwargs)
  File "/home/ubuntu/yzq/gs-python/venv3.10/lib/python3.8/site-packages/requests/sessions.py", line 589, in request
    resp = self.send(prep, **send_kwargs)
  File "/home/ubuntu/yzq/gs-python/venv3.10/lib/python3.8/site-packages/requests/sessions.py", line 703, in send
    r = adapter.send(request, **kwargs)
  File "/home/ubuntu/yzq/gs-python/venv3.10/lib/python3.8/site-packages/requests/adapters.py", line 501, in send
    raise ConnectionError(err, request=request)
requests.exceptions.ConnectionError: ('Connection aborted.', ConnectionResetError(104, 'Connection reset by peer'))
